Unable to init server: Could not connect: Connection refused
Unable to init server: Could not connect: Connection refused

(multiplexing_VH_decoder.py:388523): Gdk-CRITICAL **: 15:00:21.753: gdk_cursor_new_for_display: assertion 'GDK_IS_DISPLAY (display)' failed

(multiplexing_VH_decoder.py:388523): Gdk-CRITICAL **: 15:00:21.754: gdk_cursor_new_for_display: assertion 'GDK_IS_DISPLAY (display)' failed
inputs:
['multiplexing_VH_decoder.py', '9', '10000', '1.00', '0.00', '100', '18', '2', '4', '1']
Traceback (most recent call last):
  File "multiplexing_VH_decoder.py", line 482, in <module>
    main_with_LE()
  File "multiplexing_VH_decoder.py", line 436, in main_with_LE
    input_matrices = import_matrices(input_matrices_filename)
  File "multiplexing_VH_decoder.py", line 407, in import_matrices
    jsonfile = open(file_name, 'r')
FileNotFoundError: [Errno 2] No such file or directory: '2.json'
